Version=1
TestCase
id=CPP://-576087162648775499
Detail
message=アサーションの成功: CPPTEST_DS_GET_INTEGER("[OUT]sum") == _sum [ 期待値: 2 結果: 2 ]
line=102
file=calculation/calculation/tests/autogenerated/ソース ファイル/TestSuite_calc_c.c
uniqueId=38671817271084482
iteration=1
type=22
__Detail__
Detail
message=テスト ケースの実行が失敗しました
line=0
Thr
lang=cpp
ThrPart
clName=テスト ケースの例外が失敗
detMsg=テスト ケースの実行が失敗しました
prnMsg=テスト ケースの実行が失敗しました
Trace
clName=
metName=
fileName=calculation/calculation/tests/autogenerated/ソース ファイル/TestSuite_calc_c.c
ln=15
fhash=-752433248
__trace__
Trace
clName=
metName=
fileName=calculation/calculation/tests/autogenerated/ソース ファイル/TestSuite_calc_c.c
ln=12
fhash=442297014
__trace__
__throwable__
__throwable_top__
severity=1
uniqueId=-5860246643482575555
iteration=-1
type=21
__Detail__
__TestCase__
